2021-05-10 11:35:37.777533 >>> {command: get_health}
2021-05-10 11:35:37.931502 <<< {isError: false, response: {status: ok}, type: _extensionType, method: ext.flutter.driver}
2021-05-10 11:35:37.939449 >>> {command: request_data, timeout: 60000}
2021-05-10 11:35:40.399499 <<< {isError: false, response: {message: {"result":"false","failureDetails":["{\"methodName\":\"Add product and remove using cancel button\",\"details\":\"══╡ EXCEPTION CAUGHT BY FLUTTER TEST FRAMEWORK ╞═════════════════\\nThe following StateError was thrown running a test:\\nBad state: No element\\n\\nWhen the exception was thrown, this was the stack:\\n#0      Iterable.first (dart:core/iterable.dart:468:7)\\n#1      _FirstFinder.filter.sync_op (package:flutter_test/src/finders.dart:478:28)\\n#2      _SyncIterator.moveNext (dart:core-patch/core_patch.dart:181:26)\\n#3      Iterable.single (dart:core/iterable.dart:498:13)\\n#4      WidgetController._getElementPoint (package:flutter_test/src/controller.dart:814:47)\\n#5      WidgetController.getCenter (package:flutter_test/src/controller.dart:786:12)\\n#6      WidgetController.tap (package:flutter_test/src/controller.dart:257:18)\\n#7      main.<anonymous closure>.<anonymous closure> (file:///C:/Users/notedell/OneDrive/Documentos/Processo%20Seletivo/Supera/gameshop_supera/integration_test/app_test.dart:14:20)\\n<asynchronous suspension>\\n<asynchronous suspension>\\n(elided one frame from package:stack_trace)\\n\\nThe test description was:\\n  Add product and remove using cancel button\\n═════════════════════════════════════════════════════════════════\\n\"}"]}}, type: _extensionType, method: ext.flutter.driver}
2021-05-10 11:36:39.730108 >>> {command: get_health}
2021-05-10 11:36:39.875663 <<< {isError: false, response: {status: ok}, type: _extensionType, method: ext.flutter.driver}
2021-05-10 11:36:39.883644 >>> {command: request_data, timeout: 60000}
2021-05-10 11:36:42.307904 <<< {isError: false, response: {message: {"result":"false","failureDetails":["{\"methodName\":\"Add product and remove using cancel button\",\"details\":\"══╡ EXCEPTION CAUGHT BY FLUTTER TEST FRAMEWORK ╞═════════════════\\nThe following StateError was thrown running a test:\\nBad state: No element\\n\\nWhen the exception was thrown, this was the stack:\\n#0      Iterable.first (dart:core/iterable.dart:468:7)\\n#1      _FirstFinder.filter.sync_op (package:flutter_test/src/finders.dart:478:28)\\n#2      _SyncIterator.moveNext (dart:core-patch/core_patch.dart:181:26)\\n#3      Iterable.single (dart:core/iterable.dart:498:13)\\n#4      WidgetController._getElementPoint (package:flutter_test/src/controller.dart:814:47)\\n#5      WidgetController.getCenter (package:flutter_test/src/controller.dart:786:12)\\n#6      WidgetController.tap (package:flutter_test/src/controller.dart:257:18)\\n#7      main.<anonymous closure>.<anonymous closure> (file:///C:/Users/notedell/OneDrive/Documentos/Processo%20Seletivo/Supera/gameshop_supera/integration_test/app_test.dart:14:20)\\n<asynchronous suspension>\\n<asynchronous suspension>\\n(elided one frame from package:stack_trace)\\n\\nThe test description was:\\n  Add product and remove using cancel button\\n═════════════════════════════════════════════════════════════════\\n\"}"]}}, type: _extensionType, method: ext.flutter.driver}
2021-05-10 11:38:58.512622 >>> {command: get_health}
2021-05-10 11:38:58.656438 <<< {isError: false, response: {status: ok}, type: _extensionType, method: ext.flutter.driver}
2021-05-10 11:38:58.664415 >>> {command: request_data, timeout: 60000}
2021-05-10 11:38:59.710007 <<< {isError: false, response: {message: {"result":"false","failureDetails":["{\"methodName\":\"Add product and remove using cancel button\",\"details\":\"══╡ EXCEPTION CAUGHT BY FLUTTER TEST FRAMEWORK ╞═════════════════\\nThe following message was thrown:\\nMultiple exceptions (2) were detected during the running of the\\ncurrent test, and at least one was unexpected.\\n═════════════════════════════════════════════════════════════════\\n\"}"]}}, type: _extensionType, method: ext.flutter.driver}
2021-05-10 11:41:19.456460 >>> {command: get_health}
2021-05-10 11:41:19.609324 <<< {isError: false, response: {status: ok}, type: _extensionType, method: ext.flutter.driver}
2021-05-10 11:41:19.617812 >>> {command: request_data, timeout: 60000}
2021-05-10 11:41:22.129725 <<< {isError: false, response: {message: {"result":"false","failureDetails":["{\"methodName\":\"Add product and remove using cancel button\",\"details\":\"══╡ EXCEPTION CAUGHT BY FLUTTER TEST FRAMEWORK ╞═════════════════\\nThe following StateError was thrown running a test:\\nBad state: No element\\n\\nWhen the exception was thrown, this was the stack:\\n#0      Iterable.first (dart:core/iterable.dart:468:7)\\n#1      _FirstFinder.filter.sync_op (package:flutter_test/src/finders.dart:478:28)\\n#2      _SyncIterator.moveNext (dart:core-patch/core_patch.dart:181:26)\\n#3      Iterable.single (dart:core/iterable.dart:498:13)\\n#4      WidgetController._getElementPoint (package:flutter_test/src/controller.dart:814:47)\\n#5      WidgetController.getCenter (package:flutter_test/src/controller.dart:786:12)\\n#6      WidgetController.tap (package:flutter_test/src/controller.dart:257:18)\\n#7      main.<anonymous closure>.<anonymous closure> (file:///C:/Users/notedell/OneDrive/Documentos/Processo%20Seletivo/Supera/gameshop_supera/integration_test/app_test.dart:14:20)\\n<asynchronous suspension>\\n<asynchronous suspension>\\n(elided one frame from package:stack_trace)\\n\\nThe test description was:\\n  Add product and remove using cancel button\\n═════════════════════════════════════════════════════════════════\\n\"}"]}}, type: _extensionType, method: ext.flutter.driver}
2021-05-10 11:42:05.732799 >>> {command: get_health}
2021-05-10 11:42:05.885545 <<< {isError: false, response: {status: ok}, type: _extensionType, method: ext.flutter.driver}
2021-05-10 11:42:05.894518 >>> {command: request_data, timeout: 60000}
2021-05-10 11:42:08.206114 <<< {isError: false, response: {message: {"result":"true","failureDetails":[]}}, type: _extensionType, method: ext.flutter.driver}
2021-05-10 11:46:17.948394 >>> {command: get_health}
2021-05-10 11:46:18.106227 <<< {isError: false, response: {status: ok}, type: _extensionType, method: ext.flutter.driver}
2021-05-10 11:46:18.113204 >>> {command: request_data, timeout: 60000}
2021-05-10 11:46:20.716673 <<< {isError: false, response: {message: {"result":"false","failureDetails":["{\"methodName\":\"Add product and remove using cancel button\",\"details\":\"══╡ EXCEPTION CAUGHT BY FLUTTER TEST FRAMEWORK ╞═════════════════\\nThe following StateError was thrown running a test:\\nBad state: No element\\n\\nWhen the exception was thrown, this was the stack:\\n#0      Iterable.single (dart:core/iterable.dart:498:25)\\n#1      WidgetController._getElementPoint (package:flutter_test/src/controller.dart:814:47)\\n#2      WidgetController.getCenter (package:flutter_test/src/controller.dart:786:12)\\n#3      WidgetController.tap (package:flutter_test/src/controller.dart:257:18)\\n#4      main.<anonymous closure>.<anonymous closure> (file:///C:/Users/notedell/OneDrive/Documentos/Processo%20Seletivo/Supera/gameshop_supera/integration_test/app_test.dart:13:20)\\n<asynchronous suspension>\\n<asynchronous suspension>\\n(elided one frame from package:stack_trace)\\n\\nThe test description was:\\n  Add product and remove using cancel button\\n═════════════════════════════════════════════════════════════════\\n\"}"]}}, type: _extensionType, method: ext.flutter.driver}
2021-05-10 11:48:23.549783 >>> {command: get_health}
2021-05-10 11:48:23.698231 <<< {isError: false, response: {status: ok}, type: _extensionType, method: ext.flutter.driver}
2021-05-10 11:48:23.705222 >>> {command: request_data, timeout: 60000}
2021-05-10 11:48:26.413459 <<< {isError: false, response: {message: {"result":"false","failureDetails":["{\"methodName\":\"Add product and remove using cancel button\",\"details\":\"══╡ EXCEPTION CAUGHT BY FLUTTER TEST FRAMEWORK ╞═════════════════\\nThe following message was thrown:\\nMultiple exceptions (2) were detected during the running of the\\ncurrent test, and at least one was unexpected.\\n═════════════════════════════════════════════════════════════════\\n\"}"]}}, type: _extensionType, method: ext.flutter.driver}
2021-05-10 11:50:10.828642 >>> {command: get_health}
2021-05-10 11:50:10.980503 <<< {isError: false, response: {status: ok}, type: _extensionType, method: ext.flutter.driver}
2021-05-10 11:50:10.988393 >>> {command: request_data, timeout: 60000}
2021-05-10 11:50:13.923466 <<< {isError: false, response: {message: {"result":"false","failureDetails":["{\"methodName\":\"Add product and remove using cancel button\",\"details\":\"══╡ EXCEPTION CAUGHT BY FLUTTER TEST FRAMEWORK ╞═════════════════\\nThe following StateError was thrown running a test:\\nBad state: No element\\n\\nWhen the exception was thrown, this was the stack:\\n#0      Iterable.first (dart:core/iterable.dart:468:7)\\n#1      _FirstFinder.filter.sync_op (package:flutter_test/src/finders.dart:478:28)\\n#2      _SyncIterator.moveNext (dart:core-patch/core_patch.dart:181:26)\\n#3      Iterable.single (dart:core/iterable.dart:498:13)\\n#4      WidgetController._getElementPoint (package:flutter_test/src/controller.dart:814:47)\\n#5      WidgetController.getCenter (package:flutter_test/src/controller.dart:786:12)\\n#6      WidgetController.tap (package:flutter_test/src/controller.dart:257:18)\\n#7      main.<anonymous closure>.<anonymous closure> (file:///C:/Users/notedell/OneDrive/Documentos/Processo%20Seletivo/Supera/gameshop_supera/integration_test/app_test.dart:26:20)\\n<asynchronous suspension>\\n<asynchronous suspension>\\n(elided one frame from package:stack_trace)\\n\\nThe test description was:\\n  Add product and remove using cancel button\\n═════════════════════════════════════════════════════════════════\\n\"}"]}}, type: _extensionType, method: ext.flutter.driver}
